Workbook

Sheet Stack-Planer
A1: Stack-Planer | B1: ="Jetzt "&TEXT(G$89,"0")&" Jahre" | E1: ="Nach Massnahmen "&TEXT(G$90,"0")&" Jahre" | L1: ="Punkte: "&TEXT($A$24,"0")&" Ausgang, "&TEXT($C$24,"0")&" real, "&TEXT($G$24,"0")&" nach den Massnahmen. Rechenweg: Blatt Parameter." | Z1: Natty oder TRT (400-1000 ng/dl)
A2: Oben eintragen, was tatsaechlich laeuft und was das letzte Blutbild sagt. Unten ankreuzen, was bereits eingenommen wird und was dazukommen soll. Die drei Scores rechnen sich in Excel sofort neu, ohne dass das Programm nochmal laufen muss. Es wird nichts gespeichert und nichts an die Auswertung zurueckgemeldet. | Z2: TRT plus (1000-1400 ng/dl)
A3: KEINE THERAPIEEMPFEHLUNG. Ein Rechenmodell aus durchschnittlichen Studieneffekten, mehr nicht. Was in einen konkreten Stack gehoert, gehoert mit einem Arzt und einem erfahrenen Coach besprochen. | Z3: Blast moderat (250-350 mg/Woche)
A4: AUSGANGSWERT 80: diese Mappe kennt keine DNA-Auswertung, deshalb wird eine durchschnittliche Anlage unterstellt - jede Kategorie sitzt auf demselben Index. Im Auslieferungszustand (nichts gemessen, Natty oder TRT, keine Orale, nichts angehakt) stehen deshalb genau 80 Punkte da. Wer alle sieben Blutwerte im gruenen Band eintraegt, landet darueber; wer Load, Orale oder schlechte Werte eintraegt, darunter. Mit einer echten DNA-Auswertung steht an dieser Stelle der persoenliche Wert, und die Maluspunkte verteilen sich ungleich auf die Kategorien statt gleichmaessig. KEINE THERAPIEEMPFEHLUNG - Stacks gehoeren mit Arzt und Coach besprochen. | Z4: Blast fortgeschritten (500-750 mg/Woche)
A5: 1. Was laeuft | Z5: Blast Profi (1 g und mehr)
A6: Gesamt-Load | C6: Natty oder TRT (400-1000 ng/dl) | G6: Hebt die Maluspunkte in allen Kategorien OHNE eigenen Blutwert. Wo gemessen wurde, steckt die Dosis bereits im Wert.
A7: Anwendungsart | C7: Dauerblast (durchgehend) | G7: Blast and Cruise zaehlt nur als solches, wenn die Pause so lang ist wie der Block (Time On = Time Off, dazwischen echtes TRT). Alles andere ist Dauerblast mit Zwischenstopps - dann die erste Option waehlen. Ab Natty/TRT ohne Wirkung, weil es dort keinen Ueberschuss zu daempfen gibt. | Z7: Dauerblast (durchgehend)
A8: Geplante Anwendungsdauer | C8: 15 Jahre | G8: So viele Jahre laeuft die Last. Sie aendert den Score NICHT - der sagt, wie hart gerade gefahren wird. Sie aendert das Endalter: jedes Jahr unter Last kostet einzeln, und zwar umso mehr, je aelter man in diesem Jahr ist. Die letzte Stufe hat kein Ende - da laeuft die Uhr, bis das Budget leer ist. | Z8: Blast and Cruise (Time On = Time Off)
A9: Alter (Jahre) | C9: 30 | G9: =" Daraus: "&IF(G$87>900,"Last ohne Ausstieg",TEXT(G$87,"0")&" Jahre unter Last")&". Ein Lebensjahr kostet in diesem Alter das "&TEXT(Parameter!$D$120,"0.00")&"-fache, unter diesem Stack das "&TEXT(Parameter!$D$123*Parameter!$D$120,"0.00")&"-fache. Das Endalter steht oben in der "&"angehefteten Zeile."
Z10: <5 Jahre
A11: 2. Aktuelle Blutwerte | Z11: 10 Jahre
A12: Leer lassen, was nicht gemessen ist - dann rechnet das Blatt fuer diese Kategorie mit der Genetik weiter. Ein eingetragener Wert zaehlt zu 75 Prozent, die Anlage bleibt mit 25 Prozent stehen: eine einzelne Messung ist eine Momentaufnahme. Wo ein guter Wert steht, hat die passende Massnahme nichts mehr zu holen - genau so soll es sein. | Z12: 15 Jahre
A13: Wert | C13: Eingabe | G13: Baender (gut / mittel / schlecht) | O13: Hinweis | Z13: bis dass der Tod uns scheidet
A14: Blutdruck systolisch (mmHg) | G14: unter 115 / 115 bis 125 / 125 bis 140 / ab 140 | O14: In Ruhe und an mehreren Tagen gemessen, nicht direkt nach dem Training. Das Risiko steigt in den grossen Kohorten durchgehend ab 115/75 mmHg - es gibt keinen Sockel, unterhalb dessen es egal waere, deshalb liegt das Optimum unter 115. Die ESC nennt ab 120 erhoeht und ab 140 Bluthochdruck; ab 140 steht hier der Endlevel, weil dort gehandelt werden muss und nicht erst bei Grad 2 (160).
A15: Haematokrit (%) | G15: unter 45 / 45 bis 50 / 50 bis 54 / ueber 54 | O15: Der Wert, wegen dem die Blutspende auf dem Plan steht. 45 und 48 sind nicht dasselbe: die Blutviskositaet steigt oberhalb von rund 45 Prozent ueberproportional, und schon innerhalb des Normbereichs haben die oberen Quartile mehr Thrombosen und Herzereignisse. Deshalb liegt das Optimum unter 45, auch wenn 52 offiziell noch normal ist. Ab 48 wuerde kein Arzt eine Testosterontherapie neu beginnen, ueber 54 heisst es in der Leitlinie: Dosis runter, absetzen oder Aderlass. Nach unten hat der Wert eine Grenze, die das Modell nicht kennt - unter 38 wird es Blutarmut. | Z15: nicht gemessen
A16: LDL-Cholesterin (mmol/l) | G16: unter 1,4 (55 mg/dl) / 1,4 bis 2,6 (55-100 mg/dl) / 2,6 bis 3,4 (100-130 mg/dl) / ueber 3,4 (ueber 130 mg/dl) | O16: Das Optimum ist der ESC/EAS-Zielwert fuer SEHR hohes Risiko: unter 1,4 mmol/l (55 mg/dl). Genau dort steht ein langjaehriger Nutzer, und eine untere Schwelle, ab der es nicht mehr besser wird, ist bis heute nicht gefunden worden - ein Neugeborenes hat rund 30 mg/dl. 1,8 (70 mg/dl) ist die Behandlungsschwelle bei hohem Risiko, kein Optimum. Der Endlevel liegt bei 3,4 (130 mg/dl), nicht erst bei 4,1 (160): 160 ist die Marke fuer eine manifeste Hypercholesterinaemie, und als Alarm ist das zu spaet. Hier bringt ein Statin am meisten. | Z16: unter 115
A17: HDL-Cholesterin (mmol/l) | G17: ueber 1,3 (50 mg/dl) / 1,0 bis 1,3 (39-50 mg/dl) / 0,6 bis 1,0 (23-39 mg/dl) / unter 0,6 (unter 23 mg/dl) | O17: ACHTUNG umgekehrte Richtung: hier ist HOCH gut. Unter 1,0 mmol/l (40 mg/dl) gilt beim Mann als erniedrigt, aber der Risikoabfall geht bis rund 1,5 (60 mg/dl) weiter - deshalb liegt das Optimum ueber 1,3 (50 mg/dl) und nicht knapp ueber der Grenze zum Krankhaften. Der Endlevel liegt bei 0,6 (23 mg/dl): wer bei 0,4 ankommt, braucht keine Warnung mehr. Sehr hohe Werte ueber 2,3 (90 mg/dl) sind uebrigens auch nicht besser, aber das ist nicht das Problem dieser Gruppe. | Z17: 115 bis 125
A18: Triglyzeride (mmol/l) | G18: unter 1,0 (89 mg/dl) / 1,0 bis 1,7 (89-150 mg/dl) / 1,7 bis 3,4 (150-300 mg/dl) / ueber 3,4 (ueber 300 mg/dl) | O18: Nuechtern gemessen, sonst ist der Wert wertlos. 1,7 mmol/l (150 mg/dl) heisst nur noch normal; das Optimum liegt unter 1,0 (89 mg/dl), und dort sitzen auch die Leute mit der besten Insulinlage. Der Endlevel steht bei 3,4 (300 mg/dl) - die 5,6 (500 mg/dl), ab denen die Bauchspeicheldruese gefaehrdet ist, sind der Notfall, und ein Notfall ist keine Warnung mehr. | Z18: 125 bis 140
A19: Nuechternglukose (mg/dl) | G19: unter 80 (4,4 mmol/l) / 80 bis 95 (4,4-5,3 mmol/l) / 95 bis 110 (5,3-6,1 mmol/l) / ab 110 (ab 6,1 mmol/l) | O19: Nuechtern heisst acht Stunden nichts gegessen. Der Risikoanstieg beginnt in den Kohorten deutlich vor 100 mg/dl, also vor der offiziellen Praediabetesgrenze - deshalb liegt das Optimum unter 80. Nach ADA ist 100 bis 125 mg/dl Praediabetes und ab 126 Diabetes; der Endlevel steht hier schon bei 110, wo die WHO von einer gestoerten Nuechternglukose spricht. Eine Warnung, die auf die Diagnose wartet, ist keine mehr. Alternativ HbA1c: unter 5,0 / 5,0 bis 5,4 / 5,4 bis 5,8 / ab 5,8 Prozent. | Z19: ab 140
A20: Cystatin C (mg/l oder Kreatinin-eGFR) | G20: unter 0,80 (eGFR ueber 110) / 0,80 bis 1,00 (eGFR 85-110) / 1,00 bis 1,30 (eGFR 60-85) / ueber 1,30 (eGFR unter 60) | O20: Besser als Kreatinin, weil unabhaengig von der Muskelmasse - bei Kraftsportlern ist Kreatinin systematisch zu hoch. Die Klammerwerte sind die eGFR nach CKD-EPI fuer einen 40-jaehrigen Mann. Der Normbereich reicht bis 1,0, aber Sterblichkeit und Herzereignisse steigen schon innerhalb davon - deshalb liegt das Optimum unter 0,80. Der Endlevel steht bei 1,30, also bei eGFR 60: das ist die Grenze zur chronischen Nierenerkrankung und nicht erst Stadium G3b. WENN DU KEIN CYSTATIN C HAST: nimm die eGFR aus dem Kreatinin und ordne sie nach den Klammerwerten ein - ungenau ist besser als gar nichts. Sie faellt bei viel Muskel aber systematisch zu schlecht aus, weil Kreatinin aus dem Muskel kommt. Sieht sie schlecht aus, lass Cystatin C nachbestimmen, bevor aus einer Muskelmasse eine Nierenerkrankung wird.
Z21: nicht gemessen
A22: 3. Ergebnis | Z22: unter 45
A23: Ausgangswert (Durchschnitt) | C23: Real (Blutwerte + Load + was laeuft) | G23: Nach den geplanten Massnahmen | O23: Rechnet Excel selbst. Die drei Zahlen sind dieselbe Skala wie im DNA-Bericht: 100 waere kein einziger Negativpunkt. Der Unterschied zwischen der ersten und der zweiten Zahl ist alles, was an Dosis, Blutwerten und Medikation zusammenkommt - Dosis, Blutwerte, Medikation. Der Unterschied zwischen der zweiten und der dritten ist das, was noch zu holen ist. ACHTUNG: die Punkte sind KEIN Mittelwert ueber die Systeme. Jedes System wird einzeln bewertet, und ein System am Anschlag zieht die Zahl nach unten, auch wenn alle anderen gruen sind - die Kette reisst am schwaechsten Glied. Welches das ist, steht auf dem Block Systeme weiter unten. | Z23: 45 bis 50
A24: 80 | C24: =Parameter!$D$91 | G24: =Parameter!$D$92 | Z24: 50 bis 54
A25: Durchschnittliche Anlage, ohne Orale, ohne Blutwerte, ohne Medikation. Ein individueller Wert steht nur im DNA-Bericht. | C25: Wo gemessen wurde, zaehlt die Messung zu 75 Prozent. Aufschluesselung je System: Block Systeme weiter unten. | G25: Erst real, wenn die Zielwerte rechts erreicht werden. | Z25: ueber 54
A27: 4. Was laeuft, was geplant ist | Z27: nicht gemessen
A28: LAEUFT BEREITS zaehlt nur in Kategorien OHNE Blutwert - wo gemessen wurde, steckt die Wirkung schon im Messwert und ein zweites Mal gutschreiben waere doppelt gezaehlt. GEPLANT zaehlt ueberall, aber gedaempft nach dem Messwert: gruenes Band 0 Prozent, mittleres Band 50, rotes Band 100. Ein Statin bei LDL unter 1,7 bringt in dieser Kategorie also nichts mehr, und der Weg von 2,5 auf 1,7 zaehlt nur halb - die gefaehrliche Strecke liegt weiter oben. Schaedliche Faktoren werden NICHT gedaempft: ein SGLT2-Hemmer hebt den Haematokrit auch dann, wenn er gerade gut ist. | Z28: unter 1,4 (55 mg/dl)
A29: WAS NUR SCHADET steht unten und ist durchgehend rot hinterlegt - sie haben in diesem Modell keinen einzigen Gesundheitsnutzen. Fuer sie sind beide Ankreuzspalten gleichwertig: ob eine Substanz schon laeuft oder erst geplant ist, aendert nichts daran, was sie anrichtet, und gedaempft wird sie nie. TESTOSTERON hat bewusst keine Faktoren - es ist die Grundlast und steckt bereits im Gesamt-Load oben. Alle anderen Zeilen zeigen, was sie ZUSAETZLICH zu Testosteron auf einzelne Systeme legen. Die 17-alpha-alkylierten Oralen stehen hier einzeln mit ihren eigenen Leber-, LDL- und HDL-Faktoren - einen Sammelschalter oben gibt es nicht mehr. | Z29: 1,4 bis 2,6 (55-100 mg/dl)
A30: Achtung beim Lesen: gedaempft wird je Kategorie, nicht je Substanz. Ein Statin bei perfektem LDL kann trotzdem noch einen kleinen Gewinn zeigen - der kommt dann aus 'Gefaesse/Atherosklerose', und fuer diese Kategorie gibt es in der Liste oben keinen Blutwert. Dasselbe beim Sartan ueber den Herzmuskel. Wer das ausschliessen will, muss diese Kategorien ueber Bildgebung beurteilen lassen - ein Blutbild sagt dazu nichts. | Z30: 2,6 bis 3,4 (100-130 mg/dl)
A31: HANDLUNGSPLAN - sortiert sich selbst. Gerechnet wird, was mit dem Score passiert, wenn NUR diese eine Massnahme dazukommt, bei den Blutwerten und dem Stack, die oben stehen. Wer einen hohen Haematokrit eintraegt, findet den Aderlass hier ganz oben; wer einen guten eintraegt, findet ihn gar nicht mehr. Je Wirkstoffklasse steht nur der Beste da - Sartan und ACE-Hemmer sind dieselbe Massnahme, nicht zwei; die schwaechere steht als Alternative dahinter. Was schon laeuft oder schon geplant ist, wird nicht noch einmal vorgeschlagen, und alles andere wird gegen den Stand NACH den geplanten Massnahmen gerechnet - hakt man das Statin an, faellt der PCSK9-Hemmer sofort weg statt unveraendert stehen zu bleiben. Dieselbe Zahl steht in der Spalte 'bringt' bei jeder Substanz. | Z31: ueber 3,4 (ueber 130 mg/dl)
A32: =IFERROR(IF(LARGE($AC$40:$AC$81,1)<=0.05,"",1&". "&INDEX($A$40:$A$81,MATCH(LARGE($AC$40:$AC$81,1),$AC$40:$AC$81,0))&" ["&INDEX($D$40:$D$81,MATCH(LARGE($AC$40:$AC$81,1),$AC$40:$AC$81,0))&"]"&IF(SUMPRODUCT(($D$40:$D$81=INDEX($D$40:$D$81,MATCH(LARGE($AC$40:$AC$81,1),$AC$40:$AC$81,0)))*($AB$40:$AB$81=2)*($AA$40:$AA$81>0)*ROW($A$40:$A$81))=0,""," Alternative: "&INDEX($A$40:$A$81,SUMPRODUCT(($D$40:$D$81=INDEX($D$40:$D$81,MATCH(LARGE($AC$40:$AC$81,1),$AC$40:$AC$81,0)))*($AB$40:$AB$81=2)*($AA$40:$AA$81>0)*ROW($A$40:$A$81))-40+1))),"") | F32: =IFERROR(IF(LARGE($AC$40:$AC$81,1)<=0.05,"",TEXT(INDEX($F$40:$F$81,MATCH(LARGE($AC$40:$AC$81,1),$AC$40:$AC$81,0)),"+0.0")&" Punkte"),"")
A33: =IFERROR(IF(LARGE($AC$40:$AC$81,2)<=0.05,"",2&". "&INDEX($A$40:$A$81,MATCH(LARGE($AC$40:$AC$81,2),$AC$40:$AC$81,0))&" ["&INDEX($D$40:$D$81,MATCH(LARGE($AC$40:$AC$81,2),$AC$40:$AC$81,0))&"]"&IF(SUMPRODUCT(($D$40:$D$81=INDEX($D$40:$D$81,MATCH(LARGE($AC$40:$AC$81,2),$AC$40:$AC$81,0)))*($AB$40:$AB$81=2)*($AA$40:$AA$81>0)*ROW($A$40:$A$81))=0,""," Alternative: "&INDEX($A$40:$A$81,SUMPRODUCT(($D$40:$D$81=INDEX($D$40:$D$81,MATCH(LARGE($AC$40:$AC$81,2),$AC$40:$AC$81,0)))*($AB$40:$AB$81=2)*($AA$40:$AA$81>0)*ROW($A$40:$A$81))-40+1))),"") | F33: =IFERROR(IF(LARGE($AC$40:$AC$81,2)<=0.05,"",TEXT(INDEX($F$40:$F$81,MATCH(LARGE($AC$40:$AC$81,2),$AC$40:$AC$81,0)),"+0.0")&" Punkte"),"") | Z33: nicht gemessen
A34: =IFERROR(IF(LARGE($AC$40:$AC$81,3)<=0.05,"",3&". "&INDEX($A$40:$A$81,MATCH(LARGE($AC$40:$AC$81,3),$AC$40:$AC$81,0))&" ["&INDEX($D$40:$D$81,MATCH(LARGE($AC$40:$AC$81,3),$AC$40:$AC$81,0))&"]"&IF(SUMPRODUCT(($D$40:$D$81=INDEX($D$40:$D$81,MATCH(LARGE($AC$40:$AC$81,3),$AC$40:$AC$81,0)))*($AB$40:$AB$81=2)*($AA$40:$AA$81>0)*ROW($A$40:$A$81))=0,""," Alternative: "&INDEX($A$40:$A$81,SUMPRODUCT(($D$40:$D$81=INDEX($D$40:$D$81,MATCH(LARGE($AC$40:$AC$81,3),$AC$40:$AC$81,0)))*($AB$40:$AB$81=2)*($AA$40:$AA$81>0)*ROW($A$40:$A$81))-40+1))),"") | F34: =IFERROR(IF(LARGE($AC$40:$AC$81,3)<=0.05,"",TEXT(INDEX($F$40:$F$81,MATCH(LARGE($AC$40:$AC$81,3),$AC$40:$AC$81,0)),"+0.0")&" Punkte"),"") | Z34: ueber 1,3 (50 mg/dl)
A35: =IFERROR(IF(LARGE($AC$40:$AC$81,4)<=0.05,"",4&". "&INDEX($A$40:$A$81,MATCH(LARGE($AC$40:$AC$81,4),$AC$40:$AC$81,0))&" ["&INDEX($D$40:$D$81,MATCH(LARGE($AC$40:$AC$81,4),$AC$40:$AC$81,0))&"]"&IF(SUMPRODUCT(($D$40:$D$81=INDEX($D$40:$D$81,MATCH(LARGE($AC$40:$AC$81,4),$AC$40:$AC$81,0)))*($AB$40:$AB$81=2)*($AA$40:$AA$81>0)*ROW($A$40:$A$81))=0,""," Alternative: "&INDEX($A$40:$A$81,SUMPRODUCT(($D$40:$D$81=INDEX($D$40:$D$81,MATCH(LARGE($AC$40:$AC$81,4),$AC$40:$AC$81,0)))*($AB$40:$AB$81=2)*($AA$40:$AA$81>0)*ROW($A$40:$A$81))-40+1))),"") | F35: =IFERROR(IF(LARGE($AC$40:$AC$81,4)<=0.05,"",TEXT(INDEX($F$40:$F$81,MATCH(LARGE($AC$40:$AC$81,4),$AC$40:$AC$81,0)),"+0.0")&" Punkte"),"") | Z35: 1,0 bis 1,3 (39-50 mg/dl)
A36: =IFERROR(IF(LARGE($AC$40:$AC$81,5)<=0.05,"",5&". "&INDEX($A$40:$A$81,MATCH(LARGE($AC$40:$AC$81,5),$AC$40:$AC$81,0))&" ["&INDEX($D$40:$D$81,MATCH(LARGE($AC$40:$AC$81,5),$AC$40:$AC$81,0))&"]"&IF(SUMPRODUCT(($D$40:$D$81=INDEX($D$40:$D$81,MATCH(LARGE($AC$40:$AC$81,5),$AC$40:$AC$81,0)))*($AB$40:$AB$81=2)*($AA$40:$AA$81>0)*ROW($A$40:$A$81))=0,""," Alternative: "&INDEX($A$40:$A$81,SUMPRODUCT(($D$40:$D$81=INDEX($D$40:$D$81,MATCH(LARGE($AC$40:$AC$81,5),$AC$40:$AC$81,0)))*($AB$40:$AB$81=2)*($AA$40:$AA$81>0)*ROW($A$40:$A$81))-40+1))),"") | F36: =IFERROR(IF(LARGE($AC$40:$AC$81,5)<=0.05,"",TEXT(INDEX($F$40:$F$81,MATCH(LARGE($AC$40:$AC$81,5),$AC$40:$AC$81,0)),"+0.0")&" Punkte"),"") | Z36: 0,6 bis 1,0 (23-39 mg/dl)
A37: =IFERROR(IF(LARGE($AC$40:$AC$81,6)<=0.05,"",6&". "&INDEX($A$40:$A$81,MATCH(LARGE($AC$40:$AC$81,6),$AC$40:$AC$81,0))&" ["&INDEX($D$40:$D$81,MATCH(LARGE($AC$40:$AC$81,6),$AC$40:$AC$81,0))&"]"&IF(SUMPRODUCT(($D$40:$D$81=INDEX($D$40:$D$81,MATCH(LARGE($AC$40:$AC$81,6),$AC$40:$AC$81,0)))*($AB$40:$AB$81=2)*($AA$40:$AA$81>0)*ROW($A$40:$A$81))=0,""," Alternative: "&INDEX($A$40:$A$81,SUMPRODUCT(($D$40:$D$81=INDEX($D$40:$D$81,MATCH(LARGE($AC$40:$AC$81,6),$AC$40:$AC$81,0)))*($AB$40:$AB$81=2)*($AA$40:$AA$81>0)*ROW($A$40:$A$81))-40+1))),"") | F37: =IFERROR(IF(LARGE($AC$40:$AC$81,6)<=0.05,"",TEXT(INDEX($F$40:$F$81,MATCH(LARGE($AC$40:$AC$81,6),$AC$40:$AC$81,0)),"+0.0")&" Punkte"),"") | Z37: unter 0,6 (unter 23 mg/dl)
A39: Substanz | B39: laeuft bereits | C39: geplant | D39: Wirkstoffklasse | E39: Evidenz | F39: bringt | G39: Haematokrit | H39: HDL | I39: LDL | J39: Blutdruck | K39: Herzmuskel | L39: Gefaesse | M39: Thrombose | N39: Psyche | O39: Aorta/Lunge | P39: Triglyzeride | Q39: Rhythmus | R39: Niere | S39: Leber allg. | T39: Glukose | U39: Lp(a) | V39: E2 | W39: Punkte gibt es erst, wenn | X39: Anmerkung | Z39: nicht gemessen
A40: PCSK9-Hemmer oder Inclisiran | D40: Statin/PCSK9 | E40: A | F40: =IF(OR($B40="x",$C40="x"),"",MAX(0,Parameter!$B$36/(((SUM(G328:V328)+SUM(G331:V331))^(1/Parameter!$B$40))*Parameter!$D$88)^(1/Parameter!$B$38)-Parameter!$D$92)) | I40: =Parameter!E258 | L40: =Parameter!I258 | U40: =Parameter!H258 | W40: LDL unter 1,4 mmol/l. Lp(a) sinkt nur um 20 bis 25 Prozent - ein hoher Ausgangswert bleibt auch danach hoch. | X40: PCSK9-Hemmer senken zusaetzlich Lp(a) - das kann sonst nichts auf diesem Blatt. Wegen der Kosten werden sie aber nur an Statin-Nonresponder oder bei Unvertraeglichkeit verschrieben; rund 95 Prozent bekommen ein Statin und sonst nichts. Deshalb steht der PCSK9-Hemmer hier in derselben Klasse wie das Statin: Es zaehlt der staerkere von beiden, nicht beide zusammen. BESONDERHEIT: derzeit das einzige Mittel, das Lp(a) ueberhaupt senkt. KOPPLUNG: die Lp(a)-Wirkung ist entkoppelt, weil es fuer Lp(a) keinen Eingabewert gibt - sie bleibt also immer voll stehen. | Z40: unter 1,0 (89 mg/dl) | AA40: =IF(N(F40)=0,0,F40-ROW()/1000000) | AB40: =SUMPRODUCT(($D$40:$D$81=$D40)*($AA$40:$AA$81>AA40))+1 | AC40: =IF(AA40<=0,0,IF(AB40=1,AA40,0))
A41: Statin | D41: Statin/PCSK9 | E41: A | F41: =IF(OR($B41="x",$C41="x"),"",MAX(0,Parameter!$B$36/(((SUM(G328:V328)+SUM(G332:V332))^(1/Parameter!$B$40))*Parameter!$D$88)^(1/Parameter!$B$38)-Parameter!$D$92)) | I41: =Parameter!E255 | L41: =Parameter!I255 | T41: =Parameter!T255 | W41: LDL unter 1,8 mmol/l (70 mg/dl). Non-Responder gibt es wirklich - ohne Kontrollwert nach 6 bis 8 Wochen sind diese Punkte nur eine Annahme. | X41: BESONDERHEITEN: Rosuvastatin und Atorvastatin sind die potentesten, Pravastatin das vertraeglichste bei Muskelproblemen, Simvastatin das mit dem hoechsten Myopathierisiko. Monacolin K aus rotem Reis IST Lovastatin - nie zusaetzlich zu einem verschriebenen Statin. KOPPLUNG: auch der Plaque-Nutzen haengt am LDL, nur rund 10 Prozent laufen ueber die pleiotropen Effekte. Bei LDL unter 1,7 bringt ein Statin deshalb praktisch nichts mehr. | Z41: 1,0 bis 1,7 (89-150 mg/dl) | AA41: =IF(N(F41)=0,0,F41-ROW()/1000000) | AB41: =SUMPRODUCT(($D$40:$D$81=$D41)*($AA$40:$AA$81>AA41))+1 | AC41: =IF(AA41<=0,0,IF(AB41=1,AA41,0))
A42: Ezetimib | D42: Cholesterin-Resorptionshemmer | E42: A | F42: =IF(OR($B42="x",$C42="x"),"",MAX(0,Parameter!$B$36/(((SUM(G328:V328)+SUM(G333:V333))^(1/Parameter!$B$40))*Parameter!$D$88)^(1/Parameter!$B$38)-Parameter!$D$92)) | I42: =Parameter!E256 | L42: =Parameter!I256 | W42: LDL unter 1,8 mmol/l, meist erst zusammen mit einem Statin erreichbar. | X42: Rund 20 Prozent LDL-Senkung auf der Aufnahmeseite statt der Syntheseseite. KOPPLUNG: wirkt ausschliesslich ueber das LDL, deshalb Rest 0 in beiden Kategorien - IMPROVE-IT zeigte den Nutzen exakt proportional zur erreichten LDL-Senkung. | Z42: 1,7 bis 3,4 (150-300 mg/dl) | AA42: =IF(N(F42)=0,0,F42-ROW()/1000000) | AB42: =SUMPRODUCT(($D$40:$D$81=$D42)*($AA$40:$AA$81>AA42))+1 | AC42: =IF(AA42<=0,0,IF(AB42=1,AA42,0))
...

Sheet Parameter
A1: Parameter - hier laesst sich alles nachjustieren
A2: Spalte B ist die Stellschraube, Spalte C nennt den Wert, mit dem ausgeliefert wurde. Wer sich verstellt hat, traegt einfach den Default wieder ein. Der Stack-Planer rechnet direkt mit Spalte B - jede Aenderung wirkt sofort. Was NICHT hier steht: die Wirkfaktoren der Substanzen (Block Matrix weiter unten) und ihre Kopplung (Block Kopplung weiter unten).
A3: Die Werte sind gesetzt, nicht gemessen. Sie beruhen auf durchschnittlichen Effektstaerken aus Studien und auf Einschaetzung, wo es keine Studien gibt. Wer sie fuer zu milde oder zu hart haelt, hat moeglicherweise recht - deshalb stehen sie hier und nicht im Programmcode.
A5: 1. Gesamt-Load
A6: Multiplikator auf den Belastungsindex. Er wirkt auf den UEBERSCHUSS ueber 1, nicht auf den ganzen Wert: effektiv = 1 + (Load - 1) * Art * Dauer * Alter. Deshalb bleibt Natty/TRT immer bei 1,00 - das ist die Grundlinie, gegen die alles andere gerechnet wird.
A7: Stufe oder Groesse | B7: Wert | C7: Default | D7: Bedeutung
A8: Natty oder TRT (400-1000 ng/dl) | B8: 1 | C8: 1 | D8: Grundlinie, hier passiert nichts.
A9: TRT plus (1000-1400 ng/dl) | B9: 2.1 | C9: 2.1 | D9: Belastung dieser Stufe gegenueber der Grundlinie.
A10: Blast moderat (250-350 mg/Woche) | B10: 3 | C10: 3 | D10: Belastung dieser Stufe gegenueber der Grundlinie.
A11: Blast fortgeschritten (500-750 mg/Woche) | B11: 5 | C11: 5 | D11: Belastung dieser Stufe gegenueber der Grundlinie.
A12: Blast Profi (1 g und mehr) | B12: 8 | C12: 8 | D12: Belastung dieser Stufe gegenueber der Grundlinie.
A13: 2. Anwendungsart
A14: Daempft oder verstaerkt den Load-Ueberschuss. Ab Natty/TRT ohne Wirkung, weil es dort keinen Ueberschuss gibt.
A15: Stufe oder Groesse | B15: Wert | C15: Default | D15: Bedeutung
A16: Dauerblast (durchgehend) | B16: 1 | C16: 1 | D16: Durchgehend, kein Erholungsfenster.
A17: Blast and Cruise (Time On = Time Off) | B17: 0.6 | C17: 0.6 | D17: Nur wenn die Pause so lang ist wie der Block, mit echtem TRT dazwischen.
A18: 3. Geplante Anwendungsdauer
A19: Nur noch die Anzahl Jahre - kein eigener Daempfungsfaktor mehr. Die Dauer wirkt ueber die Jahres-Tabelle auf dem Block Lebensuhr weiter unten: jedes Jahr unter Last kostet einzeln, und zwar mit dem Jahresfaktor des Alters, in dem man es verbringt. Deshalb ist ein Jahr mit 55 teurer als eines mit 25, ohne dass irgendwo eine Altersstufe eingestellt werden muesste.
A20: Stufe oder Groesse | B20: Wert | C20: Default | D20: Bedeutung
A21: <5 Jahre | B21: 5 | C21: 5 | D21: So viele Jahre laeuft die Last.
A22: 10 Jahre | B22: 10 | C22: 10 | D22: So viele Jahre laeuft die Last.
A23: 15 Jahre | B23: 15 | C23: 15 | D23: So viele Jahre laeuft die Last.
A24: bis dass der Tod uns scheidet | B24: - | C24: - | D24: Keine Zahl. Die Uhr laeuft weiter, bis das Budget leer ist - das Endalter faellt von selbst heraus.
A25: 4. Jahresfaktor: was ein Lebensjahr kostet
A26: f(Alter) = (1 + LINEAR * (Alter - Basisalter)) * ZINS ^ (Alter - Basisalter). Der lineare Teil gibt den gleichmaessigen Zuwachs, der Zinseszinsteil sorgt dafuer, dass die Kurve mit den Jahren von selbst steiler wird. Mit den Defaults: 20 = 1,00 - 21 = 1,01 - 30 = 1,10 - 40 = 1,22 - 60 = 1,47 - 88 = 1,88. LINEAR auf 0 macht die Kurve rein exponentiell, ZINS auf 1,000 macht sie rein linear. Die ganze Tabelle steht sichtbar auf dem Block Lebensuhr weiter unten.
A27: Stufe oder Groesse | B27: Wert | C27: Default | D27: Bedeutung
A28: Basisalter (Faktor genau 1,00) | B28: 20 | C28: 20 | D28: Der Nullpunkt der Kurve. Hier kostet ein Jahr genau eine Einheit.
A29: linearer Zuwachs je Jahr | B29: 0.005 | C29: 0.005 | D29: 0,005 heisst ein halbes Prozent pro Jahr aus dem linearen Teil.
A30: Zinseszins je Jahr | B30: 1.005 | C30: 1.005 | D30: 1,005 heisst ein halbes Prozent pro Jahr auf das schon Erreichte. Zusammen mit dem linearen Teil ergibt das knapp ein Prozent, mit steigender Tendenz.
A31: Alter, ab dem gezaehlt wird | B31: 18 | C31: 18 | D31: Darunter rechnet das Modell keinen Schaden. Hier faengt auch die Tabelle an.
A32: Schadensbudget eines Lebens | B32: 97 | C32: 97 | D32: Wie viele Einheiten ein Leben hergibt. 97,0 ist die Summe der Jahresfaktoren von 18 bis 87 bei der Default-Kurve, also genau ein Leben bis 88. Diese Zahl steht BEWUSST fest und wird nicht aus der Kurve gerechnet: sonst kuerzt sich die Kurve heraus und die beiden Regler darueber bewegen gar nichts. So gesehen ist das hier der Gegenspieler - steilere Kurve heisst frueheres Ende, wer das ausgleichen will, hebt das Budget mit an. Lastfreies Ende je Kurve: 0,000/1,000 = 115 - 0,005/1,005 = 88 - 0,005/1,010 = 80 - 0,010/1,010 = 75.
A33: 5. Vom Score zum Schadensmultiplikator
A34: M = (Bezugsscore / Score) hoch Schaerfe. Das ist die Bruecke zwischen den beiden Zahlen: der Score sagt, wie hart gefahren wird, M sagt, um welchen Faktor das die Lebensuhr schneller laufen laesst. Weil das Endalter aus GENAU diesem Score kommt, koennen die beiden nicht mehr auseinanderlaufen - jede Verschlechterung im Score zieht das Endalter nach unten, jede Verbesserung schiebt es nach oben.
A35: Stufe oder Groesse | B35: Wert | C35: Default | D35: Bedeutung
A36: Bezugsscore (M = 1,00) | B36: 80 | C36: 80 | D36: Bei diesem Score laeuft die Uhr normal. 80 ist der Durchschnitt: gesunde Anlage, nichts gemessen, Natty oder TRT, keine Orale. Daraus ergibt sich auch der Basisindex 0,20, gegen den jedes System gerechnet wird.
A37: Restspielraum bei Index 1 | B37: 0.05 | C37: 0.05 | D37: Ein System auf Index 1,00 waere unendlich schaedlich. Dieser Rest deckelt das: 0,05 heisst, der schlimmstmoegliche Einzelfaktor ist 16 hoch Schaerfe.
A38: Schaerfe | B38: 1.15 | C38: 1.15 | D38: Wie hart ein belastetes System durchschlaegt. 1,00 waere proportional. Je hoeher, desto mehr entscheidet das schwaechste Glied und desto weniger der gesunde Rest. Kalibriert auf 1 g Dauerblast plus Trenbolon plus Methandienon, 15 Jahre ab 30 - das landet damit bei rund 61.
A39: Stapelung von Schaden auf einem System | B39: 1.5 | C39: 1.5 | D39: Zwei boese Stoffe auf demselben System sind mehr als die Summe der beiden. Der Lastfaktor geht als last hoch diesem Wert in die Saettigung. Bei 1,00 bleibt ein dreifach getroffenes System bei Index 0,70 stehen und das schwaechste Glied kommt nie richtig zum Tragen; ueber 2,00 laeuft es in die 1 und dann sind Oxandrolon und Oxymetholon gleich schlimm.
A40: Gewicht des schwaechsten Glieds | B40: 1 | C40: 1 | D40: Wie die fuenfzehn Systemgefahren zusammengefasst werden. 1,00 ist das gewichtete Mittel - schon damit dominiert ein System am Anschlag, weil die Kurve nach oben wegzieht. Hoeher heisst reiner Kettenbruch: bei 3,00 zaehlt praktisch nur noch das schlimmste System, der Rest verschwindet.
A41: 6. Blutwerte: Belastungsindex je Band
...
